Workbook

Sheet Comparatif
A1: Comparatif DAC / amplis portables — synthèse personnalisée pour L70 + Cayin N7
A2: Notes 1–10 selon le cahier des charges. Score pondéré compatible Excel/Gnumeric. Rang = appareils portables uniquement ; N7 et L70 sont marqués « Réf. ». Prix = repère européen quand disponible, sinon MSRP/prix de lancement converti en euros. Sources prix dans la feuille dédiée.
A3: PRODUIT & PROFIL | G3: ÉVALUATION PERSONNALISÉE — 1 À 10 | Q3: SCORE | S3: COMPARAISON & USAGE | X3: HEADFONICS | AF3: PRIX | AG3: AVIS MULTI-SOURCES
A4: Marque | B4: Modèle | C4: Type | D4: Profil sonore | E4: Atout principal | F4: Limite principale | G4: Propreté / contrôle | H4: Microdétail | I4: Profondeur avant-arrière | J4: Holographie / 3D | K4: Layering | L4: Matière / timbres | M4: Dynamique / tenue | N4: Puissance / polyvalence | O4: Nomadisme | P4: Complémentarité N7/L70 | Q4: Score perso /10 | R4: Rang | S4: Face au L70 | T4: Face au N7 | U4: Rôle conseillé | V4: Confiance | W4: Origine | X4: Score Headfonics | Y4: Type score HF | Z4: Date review HF | AA4: Page HF (reconstruite) | AB4: Lien Headfonics | AC4: Résumé HF | AD4: Statut BDD | AE4: Rang chrono HF | AF4: Prix moyen / MSRP (≈€) | AG4: Résumé avis (court) | AH4: Tonalité selon avis | AI4: Scène / détail selon avis | AJ4: Limites relevées dans les avis | AK4: Source avis principale | AL4: Nb sources avis | AM4: Confiance avis | AN4: Source avis 2 | AO4: Source avis 3 | AP4: Source avis 4 | AQ4: Statut multi-source | AR4: Types / diversité sources
A5: Cayin | B5: N7 | C5: DAP / référence | D5: Organique, fluide, texturé, très naturel | E5: Volumes, profondeur, continuité des plans, timbres | F5: Moins chirurgical/ferme qu’un ampli desktop très neutre | G5: 9.2 | H5: 9.5 | I5: 9.8 | J5: 9.7 | K5: 9.8 | L5: 10 | M5: 9.3 | N5: 8.5 | O5: 6.5 | P5: 10 | Q5: =IF(COUNT(G5:P5)=10,ROUND((G5*'Pondérations'!$B$5+H5*'Pondérations'!$B$6+I5*'Pondérations'!$B$7+J5*'Pondérations'!$B$8+K5*'Pondérations'!$B$9+L5*'Pondérations'!$B$10+M5*'Pondérations'!$B$11+N5*'Pondérations'!$B$12+O5*'Pondérations'!$B$13+P5*'Pondérations'!$B$14)/'Pondérations'!$B$16,3),"") | R5: Réf. | V5: Élevée | W5: Discussion initiale | AF5: 1757 | AG5: Le N7 est surtout apprécié pour son rendu organique, fluide et volumique. La classe A ajoute chaleur et densité, tandis que l'AB gagne en attaque, contrôle et clarté. | AH5: Organique, naturelle, légèrement chaude en classe A | AI5: Scène large et profonde, image solide, excellent relief et continuité des plans; détail intégré plutôt que sur-accentué. | AJ5: Moins incisif qu'une source très analytique; caractère et dynamique varient sensiblement entre classe A et AB. | AK5: https://www.ecoustics.com/reviews/cayin-n7/ | AL5: 4 | AM5: Élevée — 3+ sources, domaines variés | AN5: https://headfonics.com/cayin-n7-review/ | AO5: https://www.headfonia.com/cayin-n7-review/ | AP5: https://mobileaudiophile.com/daps/cayin-n7-dap-god-of-dynamism/ | AQ5: Objectif atteint | AR5: Review éditoriale: 4
A6: Topping | B6: L70 | C6: Ampli casque desktop / référence | D6: Très propre, neutre, contrôlé, ferme | E6: Fond noir, contrôle, puissance, neutralité | F6: Moins de profondeur holographique et de micro-relief | G6: 10 | H6: 8.8 | I6: 7.2 | J6: 7 | K6: 8 | L6: 8.2 | M6: 9.5 | N6: 10 | O6: 1 | P6: 6.5 | Q6: =IF(COUNT(G6:P6)=10,ROUND((G6*'Pondérations'!$B$5+H6*'Pondérations'!$B$6+I6*'Pondérations'!$B$7+J6*'Pondérations'!$B$8+K6*'Pondérations'!$B$9+L6*'Pondérations'!$B$10+M6*'Pondérations'!$B$11+N6*'Pondérations'!$B$12+O6*'Pondérations'!$B$13+P6*'Pondérations'!$B$14)/'Pondérations'!$B$16,3),"") | R6: Réf. | V6: Élevée | W6: Discussion initiale | AF6: 307 | AG6: Le L70 est décrit comme très propre, puissant et transparent, avec une séparation remarquable. Certains avis lui trouvent néanmoins une présentation plus pleine que strictement clinique. | AH6: Neutre, propre, légèrement plein selon les associations | AI6: Grande largeur, excellente séparation et précision; profondeur correcte mais rendu surtout axé sur contrôle et lisibilité. | AJ6: Peut paraître moins organique/holographique qu'une amplification discrète de caractère; très dépendant du DAC en amont. | AK6: https://primeaudio.org/topping-e70-and-l70-review/ | AL6: 5 | AM6: Élevée — 3+ sources, domaines variés | AN6: https://iiwireviews.com/topping-l70-review-head-amp-with-full-bodied-sound | AO6: https://headfonics.com/topping-l70-review/ | AP6: https://www.headfonia.com/topping-e70-l70-review/ | AQ6: Objectif atteint | AR6: Head-Fi reviews: 1; Review éditoriale: 4
A7: iBasso | B7: DC-Elite | C7: Dongle DAC/amp | D7: Neutre-naturel, très résolvant, incisif sans sécheresse | E7: Microdétail + profondeur + contours + texture | F7: Cher, consommation USB, moins organique que N7 | G7: 9.6 | H7: 9.6 | I7: 9.2 | J7: 9.2 | K7: 9.4 | L7: 9.2 | M7: 9.5 | N7: 7 | O7: 9 | P7: 9.7 | Q7: =IF(COUNT(G7:P7)=10,ROUND((G7*'Pondérations'!$B$5+H7*'Pondérations'!$B$6+I7*'Pondérations'!$B$7+J7*'Pondérations'!$B$8+K7*'Pondérations'!$B$9+L7*'Pondérations'!$B$10+M7*'Pondérations'!$B$11+N7*'Pondérations'!$B$12+O7*'Pondérations'!$B$13+P7*'Pondérations'!$B$14)/'Pondérations'!$B$16,3),"") | R7: =IF(Q7="","",1+COUNTIF($Q$7:$Q$178,">"&Q7)+COUNTIF($Q$7:Q7,Q7)-1) | V7: Élevée | W7: Discussion + Headfonics | X7: 8.6 | Y7: Reader | Z7: 45499 | AA7: 3 | AB7: https://headfonics.com/?s=iBasso+DC-Elite | AC7: Flagship dongle DAC/amp | AD7: Déjà présent | AE7: 51 | AF7: 439 | AG7: Dongle flagship très détaillé, propre et extrêmement dynamique, avec un niveau proche de certains DAP haut de gamme. | AH7: Neutre-naturel, très résolvant. | AI7: Scène franchement holographique, excellente dynamique et très bon contrôle des petits niveaux. | AJ7: Ergonomie du volume perfectible; résultat peut varier selon la source USB/téléphone. | AK7: https://headfonics.com/ibasso-dc-elite-review/ | AL7: 4 | AM7: Élevée — 3+ sources, domaines variés | AN7: https://www.head-fi.org/showcase/ibasso-dc-elite.27762/ | AO7: https://www.headfonia.com/ibasso-dc-elite-review/ | AP7: https://mobileaudiophile.com/dacs/dongle/ibasso-dc-elite-review-magic-box/ | AQ7: Objectif atteint | AR7: Head-Fi reviews: 1; Review éditoriale: 3
A8: Quloos | B8: MUB1 | C8: DAC/amp portable sur batterie | D8: Légèrement chaleureux, dense, transparent | E8: Densité, layering, profondeur verticale, puissance | F8: Un peu plus doux/moins incisif que DC-Elite | G8: 9.3 | H8: 9.1 | I8: 9.2 | J8: 9.1 | K8: 9.3 | L8: 9.4 | M8: 9.1 | N8: 9.5 | O8: 7.8 | P8: 9.5 | Q8: =IF(COUNT(G8:P8)=10,ROUND((G8*'Pondérations'!$B$5+H8*'Pondérations'!$B$6+I8*'Pondérations'!$B$7+J8*'Pondérations'!$B$8+K8*'Pondérations'!$B$9+L8*'Pondérations'!$B$10+M8*'Pondérations'!$B$11+N8*'Pondérations'!$B$12+O8*'Pondérations'!$B$13+P8*'Pondérations'!$B$14)/'Pondérations'!$B$16,3),"") | R8: =IF(Q8="","",1+COUNTIF($Q$7:$Q$178,">"&Q8)+COUNTIF($Q$7:Q8,Q8)-1) | V8: Moyenne à élevée | W8: Discussion initiale | AF8: 439 | AG8: Le MUB1 est régulièrement décrit comme naturel, dense et très propre, avec un grave profond et contrôlé, des médiums riches et un aigu détaillé sans agressivité. | AH8: Équilibrée, naturelle, légèrement chaleureuse | AI8: Scène spacieuse avec vraie profondeur, bon layering et fond noir; image précise sans sonner sèche. | AJ8: Peut sembler un peu moins tranchant qu'un dongle très analytique; le super-gain est moins adapté aux IEM sensibles. | AK8: https://moonstarreviews.net/quloos-mub1-review/ | AL8: 4 | AM8: Élevée — 3+ sources, domaines variés | AN8: https://www.head-fi.org/showcase/qls-hifi-mub1.26725/reviews | AO8: https://theheadphonelist.com/review-quloos-mub1/ | AP8: https://www.head-fi.org/threads/qls-mub-1.969455/ | AQ8: Objectif atteint | AR8: Head-Fi forum: 1; Head-Fi reviews: 1; Review éditoriale: 2
A9: Cayin | B9: RU7 | C9: Dongle DAC/amp R-2R/1-bit | D9: Fluide, organique, doux, spatial | E9: Profondeur naturelle, cohérence des timbres, image 3D | F9: Redondant avec le N7; moins incisif que DC-Elite | G9: 8.8 | H9: 9 | I9: 9.4 | J9: 9.5 | K9: 9.3 | L9: 9.7 | M9: 8.7 | N9: 7.8 | O9: 9.3 | P9: 8 | Q9: =IF(COUNT(G9:P9)=10,ROUND((G9*'Pondérations'!$B$5+H9*'Pondérations'!$B$6+I9*'Pondérations'!$B$7+J9*'Pondérations'!$B$8+K9*'Pondérations'!$B$9+L9*'Pondérations'!$B$10+M9*'Pondérations'!$B$11+N9*'Pondérations'!$B$12+O9*'Pondérations'!$B$13+P9*'Pondérations'!$B$14)/'Pondérations'!$B$16,3),"") | R9: =IF(Q9="","",1+COUNTIF($Q$7:$Q$178,">"&Q9)+COUNTIF($Q$7:Q9,Q9)-1) | V9: Élevée | W9: Discussion + Headfonics | X9: 8.6 | Y9: Reader | Z9: 45143 | AA9: 4 | AB9: https://headfonics.com/?s=Cayin+RU7 | AC9: 1-bit discrete resistor-network dongle DAC/amp | AD9: Déjà présent | AE9: 78 | AF9: 255 | AG9: Très musical et techniquement solide; restitution colorée de façon agréable, avec une excellente puissance et des modes DSD qui modifient réellement le rendu. | AH9: Organique, légèrement chaleureuse | AI9: Immersive et techniquement aboutie; bonne profondeur et cohérence spatiale | AJ9: Consommation/ergonomie dongle; câble Lightning non fourni | AK9: https://headfonics.com/cayin-ru7-review/ | AL9: 4 | AM9: Élevée — 3+ sources, domaines variés | AN9: https://www.head-fi.org/showcase/cayin-ru7.26493/reviews | AO9: https://iiwireviews.com/cayin-ru7-dac-review-fantastic-portable-sound/ | AP9: https://www.ecoustics.com/reviews/cayin-ru7-dongle-dac/ | AQ9: Objectif atteint | AR9: Head-Fi reviews: 1; Review éditoriale: 3
A10: Dethonray | B10: Clarinet | C10: DAC/amp portable sur batterie | D10: Naturel, doux, légèrement sombre, texturé | E10: Grande scène, layering, matière, douceur | F10: Moins neutre et moins incisif; microdétail un peu moins frontal | G10: 8.7 | H10: 8.7 | I10: 9.3 | J10: 9.2 | K10: 9.2 | L10: 9.6 | M10: 8.8 | N10: 8.8 | O10: 7.2 | P10: 8.8 | Q10: =IF(COUNT(G10:P10)=10,ROUND((G10*'Pondérations'!$B$5+H10*'Pondérations'!$B$6+I10*'Pondérations'!$B$7+J10*'Pondérations'!$B$8+K10*'Pondérations'!$B$9+L10*'Pondérations'!$B$10+M10*'Pondérations'!$B$11+N10*'Pondérations'!$B$12+O10*'Pondérations'!$B$13+P10*'Pondérations'!$B$14)/'Pondérations'!$B$16,3),"") | R10: =IF(Q10="","",1+COUNTIF($Q$7:$Q$178,">"&Q10)+COUNTIF($Q$7:Q10,Q10)-1) | V10: Moyenne | W10: Discussion initiale | AF10: 196 | AG10: Le Clarinet privilégie une restitution fluide, musicale et organique avec des médiums très naturels. Il conserve un bon niveau de microdétail malgré sa douceur. | AH10: Neutre-douce, légèrement chaude et organique | AI10: Scène large et ouverte, bonne profondeur et layering, fond noir; spatialisation plus enveloppante que démonstrative. | AJ10: Grave/mid-bass parfois un peu léger; extension d'aigu perfectible face aux meilleurs concurrents. | AK10: https://www.headfonia.com/dethonray-clarinet-review/ | AL10: 4 | AM10: Élevée — 3+ sources, domaines variés | AN10: https://www.head-fi.org/showcase/dethonray-clarinet.27782/reviews | AO10: https://www.audiophile-heaven.com/2025/04/the-canto-master-dethonray-clarinet-dac-headphone-amp.html | AP10: https://www.head-fi.org/threads/dethonray-clarinet-portable-dac-amp-discussion-impression-thread.975231/ | AQ10: Objectif atteint | AR10: Head-Fi forum: 1; Head-Fi reviews: 1; Review éditoriale: 2
A11: Moondrop | B11: Moonriver 3 | C11: Dongle DAC/amp | D11: Neutre, très ouvert, analytique sans être stérile | E11: Résolution, scène large/profonde, séparation | F11: Moins incarné/organique que N7 ou solutions hybrides | G11: 9.4 | H11: 9.3 | I11: 9.1 | J11: 9 | K11: 9.2 | L11: 8.6 | M11: 9.2 | N11: 8.8 | O11: 9 | P11: 9.1 | Q11: =IF(COUNT(G11:P11)=10,ROUND((G11*'Pondérations'!$B$5+H11*'Pondérations'!$B$6+I11*'Pondérations'!$B$7+J11*'Pondérations'!$B$8+K11*'Pondérations'!$B$9+L11*'Pondérations'!$B$10+M11*'Pondérations'!$B$11+N11*'Pondérations'!$B$12+O11*'Pondérations'!$B$13+P11*'Pondérations'!$B$14)/'Pondérations'!$B$16,3),"") | R11: =IF(Q11="","",1+COUNTIF($Q$7:$Q$178,">"&Q11)+COUNTIF($Q$7:Q11,Q11)-1) | V11: Élevée | W11: Discussion + Headfonics | X11: 8.7 | Y11: Award | Z11: 46144 | AA11: 1 | AB11: https://headfonics.com/?s=Moondrop+Moonriver+3 | AC11: Dual CS43198 dongle DAC, DSP, up to 500 mW | AD11: Déjà présent | AE11: 8 | AF11: 229 | AG11: Dongle très dynamique, détaillé et large, avec fond très silencieux et excellente polyvalence. | AH11: Neutre, ouvert et énergique. | AI11: Large scène, très bonne séparation et résolution. | AJ11: Pas de gain physique; plus lourd que la génération précédente. | AK11: https://headfonics.com/moondrop-moonriver-3-review/ | AL11: 3 | AM11: Élevée — 3+ sources, domaines variés | AN11: https://www.hifidaydreaming.com/post/the-future-of-portable-dac-amps-is-here-moondrop-moonriver-3-review | AO11: https://cj.sina.com.cn/articles/view/7879848900/1d5acf3c402702rlle?froms=ggmp | AQ11: Objectif atteint | AR11: Review éditoriale: 3
A12: ONIX | B12: Beta XI2 | C12: DAC/amp portable hybride | D12: Naturel, légèrement chaleureux; tubes plus organiques | E12: Corps, profondeur, double signature | F12: Moins transparent/raffiné que N7; plus encombrant | G12: 8.9 | H12: 8.8 | I12: 9.1 | J12: 9.2 | K12: 9 | L12: 9.5 | M12: 8.8 | N12: 9 | O12: 6.8 | P12: 9 | Q12: =IF(COUNT(G12:P12)=10,ROUND((G12*'Pondérations'!$B$5+H12*'Pondérations'!$B$6+I12*'Pondérations'!$B$7+J12*'Pondérations'!$B$8+K12*'Pondérations'!$B$9+L12*'Pondérations'!$B$10+M12*'Pondérations'!$B$11+N12*'Pondérations'!$B$12+O12*'Pondérations'!$B$13+P12*'Pondérations'!$B$14)/'Pondérations'!$B$16,3),"") | R12: =IF(Q12="","",1+COUNTIF($Q$7:$Q$178,">"&Q12)+COUNTIF($Q$7:Q12,Q12)-1) | V12: Moyenne | W12: Discussion + Headfonics | X12: 8.5 | Y12: Reader | Z12: 45987 | AA12: 1 | AB12: https://headfonics.com/?s=ONIX+Beta+XI2 | AC12: Hybrid solid-state/JAN6418 tube dongle DAC | AD12: Déjà présent | AE12: 16 | AF12: 349 | AG12: Deux signatures utiles : transistor propre et défini, tube plus doux et chaleureux, avec un très faible bruit de fond. | AH12: Naturel; transistor analytique, tube chaleureux. | AI12: Bon layering et placement 3D, largeur supérieure en transistor; profondeur seulement correcte. | AJ12: Accessoires basiques; profondeur pas au niveau des sources haut de gamme. | AK12: https://headfonics.com/onix-beta-xi2-review/ | AL12: 4 | AM12: Élevée — 3+ sources, domaines variés | AN12: https://www.headfonia.com/onix-beta-xi2-review/ | AO12: https://www.audiophile-heaven.com/2025/11/shanling-onix-beta-xi2-tube-usb-dongle-dac-amp-review-dual-dacs-dual-tubes-dual-fun.html | AP12: https://www.ecoustics.com/reviews/onix-beta-xi2/ | AQ12: Objectif atteint | AR12: Review éditoriale: 4
A13: MUSE HiFi | B13: M6 Double | C13: DAC/amp portable hybride | D13: Spacieux, immersif, tubes plus charnels | E13: Effet 3D, profondeur, immersion, choix tube/transistor | F13: Plus coloré, retours indépendants encore limités | G13: 8.8 | H13: 8.9 | I13: 8.9 | J13: 9 | K13: 9.2 | L13: 9.2 | M13: 9 | N13: 8.2 | O13: 6.5 | P13: 8.9 | Q13: =IF(COUNT(G13:P13)=10,ROUND((G13*'Pondérations'!$B$5+H13*'Pondérations'!$B$6+I13*'Pondérations'!$B$7+J13*'Pondérations'!$B$8+K13*'Pondérations'!$B$9+L13*'Pondérations'!$B$10+M13*'Pondérations'!$B$11+N13*'Pondérations'!$B$12+O13*'Pondérations'!$B$13+P13*'Pondérations'!$B$14)/'Pondérations'!$B$16,3),"") | R13: =IF(Q13="","",1+COUNTIF($Q$7:$Q$178,">"&Q13)+COUNTIF($Q$7:Q13,Q13)-1) | V13: Moyenne | W13: Discussion + Headfonics | X13: 8.6 | Y13: Reader | Z13: 45958 | AA13: 1 | AB13: https://headfonics.com/?s=MUSE+HiFi+M6+Double | AC13: Dual-mode transistor/JAN6418 tube portable DAC/amp | AD13: Déjà présent | AE13: 19 | AF13: 449 | AG13: Hybride très doux et musical, encore plus soyeux en mode tube, avec une bonne capacité à alimenter des casques. | AH13: Doux; tube plus lisse que transistor. | AI13: Immersif et agréable, mais la review met plus en avant le caractère que la résolution brute. | AJ13: Puissance pas exceptionnelle vu le gabarit. | AK13: https://headfonics.com/muse-hifi-m6-double-review/ | AL13: 4 | AM13: Élevée — 3+ sources, domaines variés | AN13: https://www.headfonia.com/muse-hifi-m6-double-review/ | AO13: https://www.uni-sonia.com/musehifi-m6-double/ | AP13: https://note.com/sekixyo/n/n1a59c57ce107 | AQ13: Objectif atteint | AR13: Review éditoriale: 4
A14: Questyle | B14: M15i | C14: Dongle DAC/amp | D14: Propre, doux, légèrement charnu, très spatial | E14: Image stable, profondeur naturelle, format compact | F14: Puissance plus limitée avec casques gourmands | G14: 9.3 | H14: 9.1 | I14: 9.1 | J14: 9.2 | K14: 9 | L14: 9 | M14: 8.8 | N14: 6.8 | O14: 9.6 | P14: 9 | Q14: =IF(COUNT(G14:P14)=10,ROUND((G14*'Pondérations'!$B$5+H14*'Pondérations'!$B$6+I14*'Pondérations'!$B$7+J14*'Pondérations'!$B$8+K14*'Pondérations'!$B$9+L14*'Pondérations'!$B$10+M14*'Pondérations'!$B$11+N14*'Pondérations'!$B$12+O14*'Pondérations'!$B$13+P14*'Pondérations'!$B$14)/'Pondérations'!$B$16,3),"") | R14: =IF(Q14="","",1+COUNTIF($Q$7:$Q$178,">"&Q14)+COUNTIF($Q$7:Q14,Q14)-1) | V14: Élevée | W14: Discussion initiale | AF14: 259 | AG14: Le M15i combine une signature neutre avec une légère énergie en V et une amplification très rapide. Les retours insistent sur sa résolution, sa dynamique et son image spatiale. | AH14: Neutre, légèrement vive/énergique | AI14: Imagerie et layering très précis, bonne expansion avant-arrière; sortie 4,4 mm nettement plus convaincante que la 3,5 mm. | AJ14: Peut devenir un peu brillant ou métallique avec des transducteurs déjà lumineux; puissance limitée pour certains casques. | AK14: https://www.audiodiscourse.com/2024/06/questyle-m15i-portable-dacamp-review.html | AL14: 5 | AM14: Élevée — 3+ sources, domaines variés | AN14: https://majorhifi.com/questyle-m15i-review/ | AO14: https://www.head-fi.org/showcase/questyle-m15i-%E2%80%94-mobile-headphone-amp-dac.27064/reviews | AP14: https://www.head-fi.org/threads/questyle-m12i-m15i-usb-dac-review-the-charm-of-current-mode-amplification.974037/ | AQ14: Objectif atteint | AR14: Head-Fi forum: 1; Head-Fi reviews: 1; Review éditoriale: 3
A15: Shanling | B15: UA7 | C15: Dongle DAC/amp hybride | D15: Propre, légèrement chaleureux; tube plus organique | E15: Profondeur modulable, puissance, polyvalence | F15: Moins résolvant que DC-Elite; plus coloré selon mode | G15: 9 | H15: 8.8 | I15: 8.9 | J15: 9 | K15: 8.9 | L15: 9.2 | M15: 8.8 | N15: 9 | O15: 8.5 | P15: 8.6 | Q15: =IF(COUNT(G15:P15)=10,ROUND((G15*'Pondérations'!$B$5+H15*'Pondérations'!$B$6+I15*'Pondérations'!$B$7+J15*'Pondérations'!$B$8+K15*'Pondérations'!$B$9+L15*'Pondérations'!$B$10+M15*'Pondérations'!$B$11+N15*'Pondérations'!$B$12+O15*'Pondérations'!$B$13+P15*'Pondérations'!$B$14)/'Pondérations'!$B$16,3),"") | R15: =IF(Q15="","",1+COUNTIF($Q$7:$Q$178,">"&Q15)+COUNTIF($Q$7:Q15,Q15)-1) | V15: Moyenne à élevée | W15: Discussion + Headfonics | X15: 8.6 | Y15: Award | Z15: 46050 | AA15: 1 | AB15: https://headfonics.com/?s=Shanling+UA7 | AC15: Dual JAN6418 tube dongle DAC, up to 577 mW | AD15: Déjà présent | AE15: 12 | AF15: 269 | AG15: Mélange réussi de propreté transistor et d’une légère richesse tube, sans coloration excessive. | AH15: Neutre-propre avec chaleur subtile en mode tube. | AI15: Dynamique forte, détail élevé et bonne aptitude aux casques. | AJ15: Tubes exposés et châssis anguleux. | AK15: https://headfonics.com/shanling-ua7-review/ | AL15: 4 | AM15: Élevée — 3+ sources, domaines variés | AN15: https://www.headfonia.com/shanling-ua7-review/ | AO15: https://mobileaudiophile.com/dacs/dongle/shanling-ua7-review/ | AP15: https://ichos-reviews.com/shanling-ua7-review/ | AQ15: Objectif atteint | AR15: Review éditoriale: 4
A16: iBasso | B16: DC07PRO | C16: Dongle DAC/amp | D16: Transparent, légèrement chaleureux, équilibré | E16: Valeur sûre, fond noir, largeur et placement | F16: Profondeur/holographie derrière DC-Elite | G16: 9.4 | H16: 9.1 | I16: 8.7 | J16: 8.6 | K16: 8.9 | L16: 8.9 | M16: 9 | N16: 8.7 | O16: 9.5 | P16: 8.7 | Q16: =IF(COUNT(G16:P16)=10,ROUND((G16*'Pondérations'!$B$5+H16*'Pondérations'!$B$6+I16*'Pondérations'!$B$7+J16*'Pondérations'!$B$8+K16*'Pondérations'!$B$9+L16*'Pondérations'!$B$10+M16*'Pondérations'!$B$11+N16*'Pondérations'!$B$12+O16*'Pondérations'!$B$13+P16*'Pondérations'!$B$14)/'Pondérations'!$B$16,3),"") | R16: =IF(Q16="","",1+COUNTIF($Q$7:$Q$178,">"&Q16)+COUNTIF($Q$7:Q16,Q16)-1) | V16: Élevée | W16: Discussion initiale | AF16: 189 | AG16: Le DC07PRO est jugé très neutre et propre, avec un grave rapide, un aigu aérien et une excellente résolution. Il reste légèrement plus doux que les dongles les plus incisifs. | AH16: Neutre, propre, légèrement douce | AI16: Scène large et raisonnablement profonde, excellente séparation et placement; profondeur un cran sous les meilleures sources haut de gamme. | AJ16: Layering avant-arrière pas tout à fait holographique; moins texturé et volumique que le DC-Elite. | AK16: https://www.headfonia.com/ibasso-dc07pro-review/2/ | AL16: 4 | AM16: Élevée — 3+ sources, domaines variés | AN16: https://www.head-fi.org/showcase/ibasso-dc07-pro.27359/reviews | AO16: https://moonstarreviews.net/ibasso-dc07-pro-review/ | AP16: https://androidbrick.com/ibasso-dc07pro-review/ | AQ16: Objectif atteint | AR16: Head-Fi reviews: 1; Review éditoriale: 3
A17: Shanling | B17: UA6 II | C17: Dongle DAC/amp | D17: Très propre, précis, neutre, légèrement chaleureux | E17: Fond noir, séparation, résolution, transitoires | F17: Profondeur bonne mais pas clairement holographique | G17: 9.5 | H17: 9.2 | I17: 8.6 | J17: 8.5 | K17: 9.1 | L17: 8.7 | M17: 9 | N17: 8.1 | O17: 9.5 | P17: 8.6 | Q17: =IF(COUNT(G17:P17)=10,ROUND((G17*'Pondérations'!$B$5+H17*'Pondérations'!$B$6+I17*'Pondérations'!$B$7+J17*'Pondérations'!$B$8+K17*'Pondérations'!$B$9+L17*'Pondérations'!$B$10+M17*'Pondérations'!$B$11+N17*'Pondérations'!$B$12+O17*'Pondérations'!$B$13+P17*'Pondérations'!$B$14)/'Pondérations'!$B$16,3),"") | R17: =IF(Q17="","",1+COUNTIF($Q$7:$Q$178,">"&Q17)+COUNTIF($Q$7:Q17,Q17)-1) | V17: Moyenne | W17: Discussion initiale | AF17: 219 | AG17: Le UA6 II est décrit comme très propre, contrôlé et résolvant, avec un fond noir et une légère chaleur. Son mode 8 DAC privilégie surtout ouverture et transparence. | AH17: Neutre à légèrement chaude, rapide | AI17: Bonne largeur, séparation et lecture des couches; la profondeur est correcte mais les reviews ne le décrivent pas comme franchement holographique. | AJ17: Bas-médium plutôt mince et aigu pouvant mordre avec des associations lumineuses; peu de reviews indépendantes disponibles. | AK17: https://mobileaudiophile.com/dacs/dongle/shanling-ua6-ii-review/ | AL17: 3 | AM17: Élevée — 3+ sources, domaines variés | AN17: https://hearit-hk.com/en/shanling-ua6-ii-8-cs43131-dac-2/ | AO17: https://www.notebookcheck.net/Shanling-UA6-II-portable-USB-DAC-launches-with-4-4mm-balanced-output-8-high-fidelity-DACs-and-DSD-Hi-Res-Audio.1333153.0.html | AQ17: Objectif atteint | AR17: Communauté Reddit: 1; Head-Fi reviews: 1; Review éditoriale: 1
A18: ONIX | B18: Alpha XI1 | C18: Dongle DAC/amp | D18: Musical, texturé, assez ouvert | E18: Rapport qualité/prix, puissance, matière | F18: Avis contradictoires sur profondeur/scène | G18: 9 | H18: 8.8 | I18: 8.5 | J18: 8.5 | K18: 8.6 | L18: 9 | M18: 8.9 | N18: 8.8 | O18: 9.4 | P18: 8.4 | Q18: =IF(COUNT(G18:P18)=10,ROUND((G18*'Pondérations'!$B$5+H18*'Pondérations'!$B$6+I18*'Pondérations'!$B$7+J18*'Pondérations'!$B$8+K18*'Pondérations'!$B$9+L18*'Pondérations'!$B$10+M18*'Pondérations'!$B$11+N18*'Pondérations'!$B$12+O18*'Pondérations'!$B$13+P18*'Pondérations'!$B$14)/'Pondérations'!$B$16,3),"") | R18: =IF(Q18="","",1+COUNTIF($Q$7:$Q$178,">"&Q18)+COUNTIF($Q$7:Q18,Q18)-1) | V18: Moyenne | W18: Discussion + Headfonics | X18: 7.9 | Y18: Reader | Z18: 45593 | AA18: 3 | AB18: https://headfonics.com/?s=ONIX+Alpha+XI1 | AC18: Dual CS43198 dongle DAC, up to 500 mW | AD18: Déjà présent | AE18: 45 | AF18: 109 | AG18: Très bon rapport qualité/prix, puissant et jugé parmi les meilleurs dongles autour de 200 $. | AH18: Plutôt neutre/équilibré. | AI18: Bonne qualité sonore globale et bonne réserve de puissance. | AJ18: Format assez volumineux; low gain encore relativement fort. | AK18: https://headfonics.com/onix-alpha-xi1-review/ | AL18: 4 | AM18: Élevée — 3+ sources, domaines variés | AN18: https://www.headfonia.com/onix-alpha-xi1-review/ | AO18: https://www.audiophile-heaven.com/2024/07/shanling-onix-alpha-xi1-bold-sound-good-function-dac-amp.html | AP18: https://www.reddit.com/r/headphones/comments/1dnbl2j | AQ18: Objectif atteint | AR18: Communauté Reddit: 1; Review éditoriale: 3
A19: xDuoo | B19: XD05 BAL 2 | C19: DAC/amp portable sur batterie | D19: Charnu, doux, puissant, plutôt sombre | E19: Puissance, matière, évolutivité par AOP | F19: Encombrant; moins incisif et moins micro-résolvant | G19: 8.6 | H19: 8.5 | I19: 8.7 | J19: 8.4 | K19: 8.8 | L19: 9.2 | M19: 9.2 | N19: 10 | O19: 5.5 | P19: 8.2 | Q19: =IF(COUNT(G19:P19)=10,ROUND((G19*'Pondérations'!$B$5+H19*'Pondérations'!$B$6+I19*'Pondérations'!$B$7+J19*'Pondérations'!$B$8+K19*'Pondérations'!$B$9+L19*'Pondérations'!$B$10+M19*'Pondérations'!$B$11+N19*'Pondérations'!$B$12+O19*'Pondérations'!$B$13+P19*'Pondérations'!$B$14)/'Pondérations'!$B$16,3),"") | R19: =IF(Q19="","",1+COUNTIF($Q$7:$Q$178,">"&Q19)+COUNTIF($Q$7:Q19,Q19)-1) | V19: Élevée | W19: Discussion + Headfonics | X19: 8 | Y19: Reader | Z19: 45184 | AA19: 4 | AB19: https://headfonics.com/?s=xDuoo+XD05+BAL+2 | AC19: High-power battery portable DAC/amp | AD19: Déjà présent | AE19: 76 | AF19: 429 | AG19: Portable très puissant, riche en ton et en texture, avec un grave convaincant et une restitution plutôt douce. | AH19: Charnue, douce, plutôt sombre | AI19: Bonne ampleur et dynamique, davantage axée matière que lumière dans le haut | AJ19: Aigu parfois trop lisse; médium un peu en retrait; encombrant | AK19: https://headfonics.com/xduoo-xd05-bal-2-review/ | AL19: 3 | AM19: Élevée — 3+ sources, domaines variés | AN19: https://www.arkaudio.se/en/headphones/headphones/xduoo-xd05-bal2-portable-dac-tube-headphone-amplifier.html | AO19: https://uk.testseek.com/home-electronics/hifi/dac/xduoo-xd05-bal-2-p-d129f994-2837-8d55-1622-1ce104837e79.html | AQ19: Objectif atteint | AR19: Review éditoriale: 3
A20: Dethonray | B20: Pegasus SG1 | C20: Récepteur Bluetooth DAC/amp | D20: Charnu, énergique, grave présent, aigu calme | E20: Grande scène, impact, relief en Bluetooth | F20: Bluetooth uniquement; coloré; souffle possible IEM sensibles | G20: 8.2 | H20: 8.1 | I20: 9 | J20: 8.9 | K20: 8.7 | L20: 9.4 | M20: 9 | N20: 8.7 | O20: 7.5 | P20: 7.8 | Q20: =IF(COUNT(G20:P20)=10,ROUND((G20*'Pondérations'!$B$5+H20*'Pondérations'!$B$6+I20*'Pondérations'!$B$7+J20*'Pondérations'!$B$8+K20*'Pondérations'!$B$9+L20*'Pondérations'!$B$10+M20*'Pondérations'!$B$11+N20*'Pondérations'!$B$12+O20*'Pondérations'!$B$13+P20*'Pondérations'!$B$14)/'Pondérations'!$B$16,3),"") | R20: =IF(Q20="","",1+COUNTIF($Q$7:$Q$178,">"&Q20)+COUNTIF($Q$7:Q20,Q20)-1) | V20: Moyenne | W20: Discussion initiale | AF20: 351 | AG20: Le Pegasus SG1 vise une écoute naturelle et musicale, légèrement chaude, avec des médiums séduisants. Sa restitution est davantage charnelle que strictement analytique. | AH20: Neutre-chaude, douce et musicale | AI20: Bonne profondeur et bon layering mais largeur plus modérée; séparation correcte et présentation cohérente. | AJ20: Grave pas toujours très texturé/impactant; Bluetooth uniquement et léger bruit possible avec IEM très sensibles. | AK20: https://www.headfonia.com/dethonray-pegasus-sg1-review/2/ | AL20: 3 | AM20: Élevée — 3+ sources, domaines variés | AN20: https://www.head-fi.org/showcase/dethonray-pegasus-sg1.26154/ | AO20: https://www.headphonesty.com/2020/12/best-portable-dac-amp-combo/ | AQ20: Objectif atteint | AR20: Head-Fi reviews: 1; Review éditoriale: 2
A21: Shanling | B21: H5 MQA | C21: DAC/amp portable sur batterie | D21: Chaud, fluide, grave généreux | E21: Puissance, autonomie, fonctions, lecture microSD | F21: Moins précis/spatial; impédance sortie à surveiller avec IEM | G21: 8.4 | H21: 8.3 | I21: 8.6 | J21: 8.5 | K21: 8.5 | L21: 9.2 | M21: 8.7 | N21: 9.5 | O21: 6.5 | P21: 8 | Q21: =IF(COUNT(G21:P21)=10,ROUND((G21*'Pondérations'!$B$5+H21*'Pondérations'!$B$6+I21*'Pondérations'!$B$7+J21*'Pondérations'!$B$8+K21*'Pondérations'!$B$9+L21*'Pondérations'!$B$10+M21*'Pondérations'!$B$11+N21*'Pondérations'!$B$12+O21*'Pondérations'!$B$13+P21*'Pondérations'!$B$14)/'Pondérations'!$B$16,3),"") | R21: =IF(Q21="","",1+COUNTIF($Q$7:$Q$178,">"&Q21)+COUNTIF($Q$7:Q21,Q21)-1) | V21: Moyenne | W21: Discussion + Headfonics | X21: 8.3 | Y21: Reader | Z21: 45185 | AA21: 4 | AB21: https://headfonics.com/?s=Shanling+H5 | AC21: Battery portable DAC/amp | AD21: Déjà présent | AE21: 75 | AF21: 325 | AG21: DAC/amp polyvalent au son expressif, doux et puissant; restitution plaisante plus orientée musicalité que neutralité stricte. | AH21: Douce, chaleureuse, expressive | AI21: Bonne ampleur et puissance; présentation fluide plutôt que très analytique | AJ21: Impédance de sortie élevée, attention aux IEM sensibles | AK21: https://headfonics.com/shanling-h5-review/ | AL21: 3 | AM21: Élevée — 3+ sources, domaines variés | AN21: https://www.headfonia.com/shanling-h5-review/ | AO21: https://fr.testseek.com/electromenager/hifi/dac/shanling-h5-p-20b8dfcf-3635-15fc-9b6d-5aaade081297.html | AQ21: Objectif atteint | AR21: Review éditoriale: 3
A22: xDuoo | B22: POKE II | C22: DAC/amp portable sur batterie | D22: Équilibré, bonne scène, plutôt polyvalent | E22: Profondeur/hauteur correctes, puissance, fonctions | F22: Génération plus ancienne; moins raffiné que MUB1/DC-Elite | G22: 8.5 | H22: 8.4 | I22: 8.7 | J22: 8.6 | K22: 8.6 | L22: 8.7 | M22: 8.6 | N22: 9 | O22: 6.8 | P22: 8 | Q22: =IF(COUNT(G22:P22)=10,ROUND((G22*'Pondérations'!$B$5+H22*'Pondérations'!$B$6+I22*'Pondérations'!$B$7+J22*'Pondérations'!$B$8+K22*'Pondérations'!$B$9+L22*'Pondérations'!$B$10+M22*'Pondérations'!$B$11+N22*'Pondérations'!$B$12+O22*'Pondérations'!$B$13+P22*'Pondérations'!$B$14)/'Pondérations'!$B$16,3),"") | R22: =IF(Q22="","",1+COUNTIF($Q$7:$Q$178,">"&Q22)+COUNTIF($Q$7:Q22,Q22)-1) | V22: Moyenne | W22: Discussion + Headfonics | X22: 8.3 | Y22: Reader | Z22: 44769 | AA22: 5 | AB22: https://headfonics.com/?s=xDuoo+POKE+II | AC22: Battery portable DAC/amp | AD22: Déjà présent | AE22: 100 | AF22: 343 | AG22: Son propre et peu coloré avec beaucoup de puissance; bon sur la dynamique et assez tolérant avec les enregistrements moyens. | AH22: Neutre, propre | AI22: Bonne dynamique et polyvalence; spatialisation correcte sans accent marqué sur le relief | AJ22: Bluetooth de portée moyenne; entrées limitées USB/BT | AK22: https://headfonics.com/xduoo-poke-ii-review/ | AL22: 3 | AM22: Élevée — 3+ sources, domaines variés | AN22: https://www.head-fi.org/showcase/xduoo-poke-ii.25877/reviews | AO22: https://www.headfonia.com/xduoo-poke-ii-review/ | AQ22: Objectif atteint | AR22: Head-Fi reviews: 1; Review éditoriale: 2
A23: FiiO | B23: BTR17 | C23: Bluetooth DAC/amp | D23: Neutre, rapide, propre, fonctionnel | E23: Bluetooth, PEQ, puissance, polyvalence | F23: Spatialité/profondeur moins organiques; assez proche du L70 | G23: 9.3 | H23: 8.9 | I23: 8.3 | J23: 8.2 | K23: 8.7 | L23: 8.5 | M23: 9 | N23: 9.2 | O23: 9.8 | P23: 7.8 | Q23: =IF(COUNT(G23:P23)=10,ROUND((G23*'Pondérations'!$B$5+H23*'Pondérations'!$B$6+I23*'Pondérations'!$B$7+J23*'Pondérations'!$B$8+K23*'Pondérations'!$B$9+L23*'Pondérations'!$B$10+M23*'Pondérations'!$B$11+N23*'Pondérations'!$B$12+O23*'Pondérations'!$B$13+P23*'Pondérations'!$B$14)/'Pondérations'!$B$16,3),"") | R23: =IF(Q23="","",1+COUNTIF($Q$7:$Q$178,">"&Q23)+COUNTIF($Q$7:Q23,Q23)-1) | V23: Élevée | W23: Discussion initiale | AF23: 199 | AG23: Le BTR17 est apprécié pour son équilibre neutre, vif et très propre. En USB il offre une restitution crisp, dynamique et détaillée avec beaucoup de polyvalence. | AH23: Neutre, vive, légèrement sèche | AI23: Scène large et haute, transitoires rapides et bonne séparation; l'USB conserve davantage de microdétails que le Bluetooth. | AJ23: Bluetooth réduit un peu la finesse et l'extension; le grave peut manquer de matière pour qui cherche une présentation organique. | AK23: https://headfonics.com/fiio-btr17-review/ | AL23: 4 | AM23: Élevée — 3+ sources, domaines variés | AN23: https://www.head-fi.org/showcase/fiio-btr17.28043/reviews | AO23: https://www.techradar.com/audio/hi-fi/fiio-btr17-review | AP23: https://mobileaudiophile.com/dacs/dongle/fiio-btr17-review/ | AQ23: Objectif atteint | AR23: Head-Fi reviews: 1; Review éditoriale: 3
A24: FiiO | B24: QX13 | C24: Dongle DAC/amp | D24: Très propre, détaillé, énergique | E24: Puissance, fonctions, PEQ, résolution | F24: Peut rester trop “technique” / proche du L70 | G24: 9.5 | H24: 9.2 | I24: 8.4 | J24: 8.3 | K24: 8.9 | L24: 8.4 | M24: 9.4 | N24: 9.7 | O24: 9.2 | P24: 7.7 | Q24: =IF(COUNT(G24:P24)=10,ROUND((G24*'Pondérations'!$B$5+H24*'Pondérations'!$B$6+I24*'Pondérations'!$B$7+J24*'Pondérations'!$B$8+K24*'Pondérations'!$B$9+L24*'Pondérations'!$B$10+M24*'Pondérations'!$B$11+N24*'Pondérations'!$B$12+O24*'Pondérations'!$B$13+P24*'Pondérations'!$B$14)/'Pondérations'!$B$16,3),"") | R24: =IF(Q24="","",1+COUNTIF($Q$7:$Q$178,">"&Q24)+COUNTIF($Q$7:Q24,Q24)-1) | V24: Moyenne à élevée | W24: Discussion + Headfonics | X24: 8.5 | Y24: Reader | Z24: 45892 | AA24: 2 | AB24: https://headfonics.com/?s=FiiO+QX13 | AC24: ES9027SPRO high-end dongle DAC with color display | AD24: Déjà présent | AE24: 25 | AF24: 199 | AG24: Dongle de niveau presque desktop, très puissant, détaillé et ambitieux, avec une forte sensation de présence. | AH24: Clair, vivant, médiums présents. | AI24: Très bon layering, beaucoup de nuances et excellente puissance. | AJ24: Puissance maximale exige une seconde alimentation; consommation importante. | AK24: https://headfonics.com/fiio-qx13-review/ | AL24: 4 | AM24: Élevée — 3+ sources, domaines variés | AN24: https://www.headfonia.com/fiio-qx13-review/ | AO24: https://mobileaudiophile.com/dacs/dongle/fiio-qx13-review-when-portable-audio-grows-up/ | AP24: https://primeaudio.org/fiio-qx13-review/ | AQ24: Objectif atteint | AR24: Review éditoriale: 4
A25: SMSL | B25: DS20 | C25: DAC/amp portable | D25: Propre, large, résolvant | E25: Largeur, puissance, netteté | F25: Scène plus large que profonde; layering avant/arrière moyen | G25: 9.4 | H25: 9.1 | I25: 8 | J25: 7.8 | K25: 8.2 | L25: 8.4 | M25: 9.1 | N25: 9.2 | O25: 8.3 | P25: 7.2 | Q25: =IF(COUNT(G25:P25)=10,ROUND((G25*'Pondérations'!$B$5+H25*'Pondérations'!$B$6+I25*'Pondérations'!$B$7+J25*'Pondérations'!$B$8+K25*'Pondérations'!$B$9+L25*'Pondérations'!$B$10+M25*'Pondérations'!$B$11+N25*'Pondérations'!$B$12+O25*'Pondérations'!$B$13+P25*'Pondérations'!$B$14)/'Pondérations'!$B$16,3),"") | R25: =IF(Q25="","",1+COUNTIF($Q$7:$Q$178,">"&Q25)+COUNTIF($Q$7:Q25,Q25)-1) | V25: Moyenne | W25: Discussion + Headfonics | X25: 8.3 | Y25: Reader | Z25: 45899 | AA25: 2 | AB25: https://headfonics.com/?s=SMSL+DS20 | AC25: Quad CS43131 portable DAC/amp, up to 500 mW | AD25: Déjà présent | AE25: 24 | AF25: 199 | AG25: Portable énergique, avec grave rapide et très bien contrôlé, médiums clairs et bonne dynamique. | AH25: Grave énergique, médiums neutres. | AI25: Bonne dynamique et définition; moins axé douceur. | AJ25: Aigu pas toujours très lisse. | AK25: https://headfonics.com/smsl-ds20-review/ | AL25: 3 | AM25: Élevée — 3+ sources, domaines variés | AN25: https://primeaudio.org/smsl-ds20-review/ | AO25: https://headphonesandcoffee.home.blog/2025/09/22/smsl-ds20/ | AQ25: Objectif atteint | AR25: Review éditoriale: 3
A26: MUSE HiFi | B26: M5 Ultra | C26: DAC/amp portable hybride | D26: Doux, charnu, tubes plus profonds | E26: Corps médium, profondeur, caractère tubes | F26: Sous-grave/impédance/microdétail peuvent varier selon charge | G26: 8.5 | H26: 8.4 | I26: 8.8 | J26: 8.9 | K26: 8.7 | L26: 9.3 | M26: 8.6 | N26: 8.6 | O26: 7 | P26: 8 | Q26: =IF(COUNT(G26:P26)=10,ROUND((G26*'Pondérations'!$B$5+H26*'Pondérations'!$B$6+I26*'Pondérations'!$B$7+J26*'Pondérations'!$B$8+K26*'Pondérations'!$B$9+L26*'Pondérations'!$B$10+M26*'Pondérations'!$B$11+N26*'Pondérations'!$B$12+O26*'Pondérations'!$B$13+P26*'Pondérations'!$B$14)/'Pondérations'!$B$16,3),"") | R26: =IF(Q26="","",1+COUNTIF($Q$7:$Q$178,">"&Q26)+COUNTIF($Q$7:Q26,Q26)-1) | V26: Moyenne | W26: Discussion + Headfonics | X26: 8.1 | Y26: Reader | Z26: 45800 | AA26: 2 | AB26: https://headfonics.com/?s=MUSE+HiFi+M5+Ultra | AC26: Bluetooth ES9038Q2M tube/solid-state portable DAC/amp | AD26: Déjà présent | AE26: 32 | AF26: 269 | AG26: Très bon rendu dans les deux modes, avec une restitution tube naturelle et vivante et un transistor également convaincant. | AH26: Naturel; tube plus chaleureux. | AI26: Bonne transparence et silence de fond. | AJ26: Construction/commandes légèrement perfectibles. | AK26: https://headfonics.com/muse-hifi-m5-ultra-review/ | AL26: 4 | AM26: Élevée — 3+ sources, domaines variés | AN26: https://www.head-fi.org/showcase/muse-hifi-m5-ultra.28169/reviews | AO26: https://www.headfonia.com/muse-hifi-m5-ultra-review/ | AP26: https://primeaudio.org/muse-hifi-m5-ultra-review/ | AQ26: Objectif atteint | AR26: Head-Fi reviews: 1; Review éditoriale: 3
A27: Topping | B27: G5 | C27: DAC/amp portable sur batterie | D27: Très neutre, très propre, très contrôlé | E27: Mesures, puissance, fond noir | F27: Redondant avec L70; peu de gain en holographie | G27: 9.8 | H27: 9 | I27: 8 | J27: 7.8 | K27: 8.5 | L27: 8.2 | M27: 9.3 | N27: 9.8 | O27: 6.5 | P27: 6.8 | Q27: =IF(COUNT(G27:P27)=10,ROUND((G27*'Pondérations'!$B$5+H27*'Pondérations'!$B$6+I27*'Pondérations'!$B$7+J27*'Pondérations'!$B$8+K27*'Pondérations'!$B$9+L27*'Pondérations'!$B$10+M27*'Pondérations'!$B$11+N27*'Pondérations'!$B$12+O27*'Pondérations'!$B$13+P27*'Pondérations'!$B$14)/'Pondérations'!$B$16,3),"") | R27: =IF(Q27="","",1+COUNTIF($Q$7:$Q$178,">"&Q27)+COUNTIF($Q$7:Q27,Q27)-1) | V27: Élevée | W27: Discussion initiale | AF27: 299 | AG27: Le G5 propose un rendu très propre, dynamique et précis, avec un aigu net et une bonne résolution. Il privilégie la transparence plutôt que la coloration. | AH27: Neutre, propre, dynamique | AI27: Scène aérée et spacieuse avec placement précis, bonne largeur et profondeur; fond sombre. | AJ27: Caractère plutôt technique et peu coloré; ne constitue pas le meilleur choix si l'objectif est d'ajouter matière ou chaleur. | AK27: https://moonstarreviews.net/topping-g5-portable-dac-amplifier-review/ | AL27: 3 | AM27: Élevée — 3+ sources, domaines variés | AN27: https://www.head-fi.org/showcase/topping-g5.26030/reviews | AO27: https://iegems.nk-tran.com/2022/12/16/review-Topping-G5.html | AQ27: Objectif atteint | AR27: Head-Fi reviews: 1; Review éditoriale: 2
A28: Shanling | B28: UA6 | C28: Dongle DAC/amp | D28: Transparent, spacieux, légèrement chaleureux | E28: Scène, transparence, douceur | F28: UA6 II plus abouti; moins de recul dans notre comparaison | G28: 9.1 | H28: 8.8 | I28: 8.6 | J28: 8.7 | K28: 8.7 | L28: 9 | M28: 8.8 | N28: 8.5 | O28: 9.5 | P28: 8.2 | Q28: =IF(COUNT(G28:P28)=10,ROUND((G28*'Pondérations'!$B$5+H28*'Pondérations'!$B$6+I28*'Pondérations'!$B$7+J28*'Pondérations'!$B$8+K28*'Pondérations'!$B$9+L28*'Pondérations'!$B$10+M28*'Pondérations'!$B$11+N28*'Pondérations'!$B$12+O28*'Pondérations'!$B$13+P28*'Pondérations'!$B$14)/'Pondérations'!$B$16,3),"") | R28: =IF(Q28="","",1+COUNTIF($Q$7:$Q$178,">"&Q28)+COUNTIF($Q$7:Q28,Q28)-1) | V28: Moyenne | W28: Discussion initiale | AF28: 179 | AG28: Le UA6 original est un dongle très propre et détaillé, avec une restitution neutre et un bruit de fond très faible. Il met l'accent sur la lisibilité et l'organisation. | AH28: Neutre, propre, légèrement maigre selon les associations | AI28: Scène large avec profondeur/hauteur convaincantes, imagerie précise et bonne séparation. | AJ28: Peut paraître un peu lean ou peu charnu; la synergie avec des casques/IEM déjà clairs est importante. | AK28: https://headfonics.com/shanling-ua6-review/ | AL28: 4 | AM28: Élevée — 3+ sources, domaines variés | AN28: https://www.head-fi.org/showcase/shanling-ua6.28189/reviews | AO28: https://www.headfonia.com/shanling-ua6-review/ | AP28: https://primeaudio.org/shanling-ua6-review/ | AQ28: Objectif atteint | AR28: Head-Fi reviews: 1; Review éditoriale: 3
A29: Questyle | B29: M15C | C29: Dongle DAC/amp | D29: Propre, fluide, légèrement chaleureux | E29: Image stable, compacité, musicalité Questyle | F29: Moins ambitieux/puissant que M15i | G29: 9.1 | H29: 8.8 | I29: 8.8 | J29: 8.9 | K29: 8.8 | L29: 8.4 | M29: 8.7 | N29: 8.5 | O29: 8 | P29: 8.5 | Q29: =IF(COUNT(G29:P29)=10,ROUND((G29*'Pondérations'!$B$5+H29*'Pondérations'!$B$6+I29*'Pondérations'!$B$7+J29*'Pondérations'!$B$8+K29*'Pondérations'!$B$9+L29*'Pondérations'!$B$10+M29*'Pondérations'!$B$11+N29*'Pondérations'!$B$12+O29*'Pondérations'!$B$13+P29*'Pondérations'!$B$14)/'Pondérations'!$B$16,3),"") | R29: =IF(Q29="","",1+COUNTIF($Q$7:$Q$178,">"&Q29)+COUNTIF($Q$7:Q29,Q29)-1) | V29: Moyenne | W29: Discussion + Headfonics | X29: 8 | Y29: Reader | Z29: 45663 | AA29: 3 | AB29: https://headfonics.com/?s=Questyle+M15C | AC29: Balanced dongle DAC; updated M15 family | AD29: Déjà présent | AE29: 41 | AF29: 129 | AG29: Dongle solide, bien construit et suffisamment puissant, avec une qualité sonore globalement convaincante. | AH29: Neutre/Questyle propre. | AI29: Bonne qualité générale, sans point spatial majeur mis en avant. | AJ29: Volume minimum trop élevé; gain haut peu influent. | AK29: https://headfonics.com/questyle-m15c-review/ | AL29: 4 | AM29: Élevée — 3+ sources, domaines variés | AN29: https://www.head-fi.org/showcase/questyle-m15c.27912/reviews | AO29: https://www.ecoustics.com/reviews/questyle-m15c/ | AP29: https://www.pocnetwork.net/product-reviews/questyle-m15c-portable-headphone-amp/ | AQ29: Objectif atteint | AR29: Head-Fi reviews: 1; Review éditoriale: 3
A30: iBasso | B30: DC-Tonfa | C30: Dongle DAC/amp R-2R | D30: Prometteur: texture R-2R + précision iBasso | E30: Potentiel compromis naturel / résolution / profondeur | F30: Très récent; manque encore de recul indépendant | G30: 9.1 | H30: 8.9 | I30: 9.3 | J30: 9.2 | K30: 9.2 | L30: 9.2 | M30: 8.9 | N30: 8.7 | O30: 9 | P30: 9.3 | Q30: =IF(COUNT(G30:P30)=10,ROUND((G30*'Pondérations'!$B$5+H30*'Pondérations'!$B$6+I30*'Pondérations'!$B$7+J30*'Pondérations'!$B$8+K30*'Pondérations'!$B$9+L30*'Pondérations'!$B$10+M30*'Pondérations'!$B$11+N30*'Pondérations'!$B$12+O30*'Pondérations'!$B$13+P30*'Pondérations'!$B$14)/'Pondérations'!$B$16,3),"") | R30: =IF(Q30="","",1+COUNTIF($Q$7:$Q$178,">"&Q30)+COUNTIF($Q$7:Q30,Q30)-1) | V30: Faible / provisoire | W30: Discussion initiale | AF30: 292 | AG30: Les premiers essais du DC-Tonfa décrivent un R2R résolvant mais plus doux sur les contours, avec une sensation analogique, humide et naturelle plutôt qu'une précision agressive. | AH30: Naturelle, analogique, douce | AI30: Image fluide et vivante; les filtres modifient largeur, position des voix et réverbération, avec une bonne sensation de relief. | AJ30: Produit très récent: peu de recul et de comparaisons indépendantes; conclusions encore provisoires. | AK30: https://av.watch.impress.co.jp/docs/review/review/2126352.html | AL30: 3 | AM30: Élevée — 3+ sources, domaines variés | AN30: https://www.e-earphone.jp/blogs/feature/dc-tonfa_review | AO30: https://kajetblog.com/ibasso-dc-tonfa-4/ | AQ30: Objectif atteint | AR30: Review éditoriale: 3
A31: Questyle | B31: M18i Max | C31: Portable Amp/DAC (Headfonics) | D31: Neutre-référence avec légère chaleur et médiums un peu en avant. | E31: Microdétail, propreté/contrôle, dynamique | F31: Puissance assez limitée pour les casques très exigeants | G31: 9.4 | H31: 9.2 | I31: 8.8 | J31: 8.5 | K31: 9 | L31: 8.8 | M31: 9.1 | N31: 7 | O31: 8 | P31: 8.6 | Q31: =IF(COUNT(G31:P31)=10,ROUND((G31*'Pondérations'!$B$5+H31*'Pondérations'!$B$6+I31*'Pondérations'!$B$7+J31*'Pondérations'!$B$8+K31*'Pondérations'!$B$9+L31*'Pondérations'!$B$10+M31*'Pondérations'!$B$11+N31*'Pondérations'!$B$12+O31*'Pondérations'!$B$13+P31*'Pondérations'!$B$14)/'Pondérations'!$B$16,3),"") | R31: =IF(Q31="","",1+COUNTIF($Q$7:$Q$178,">"&Q31)+COUNTIF($Q$7:Q31,Q31)-1) | V31: Élevée | W31: Headfonics import | X31: 8.7 | Y31: Award | Z31: 46223 | AA31: 1 | AB31: https://headfonics.com/?s=Questyle+M18i+Max | AC31: ESS ES9219Q wireless portable DAC/amp | AD31: Ajout Headfonics | AE31: 1 | AF31: 307 | AG31: Très performant et musical pour un portable, avec un fond propre, une excellente résolution et une dynamique vive. | AH31: Neutre-référence avec légère chaleur et médiums un peu en avant. | AI31: Scène réaliste, bonne profondeur, layering précis et microdynamique très lisible. | AJ31: Puissance assez limitée pour les casques très exigeants; Bluetooth moins convaincant que l’USB. | AK31: https://headfonics.com/questyle-m18i-max-review/ | AL31: 4 | AM31: Élevée — 3+ sources, domaines variés | AN31: https://www.headfonia.com/questyle-m18i-max-review/ | AO31: https://kajetblog.com/questyle-m18i/ | AP31: https://www.milik.ai/articles/90800bdc7e | AQ31: Objectif atteint | AR31: Review éditoriale: 4
A32: AFUL | B32: ICEBORNE | C32: Portable Amp/DAC (Headfonics) | D32: Neutre/analytique mais non fatigant. | E32: Propreté/contrôle, image 3d, profondeur | F32: Réserve de puissance limitée avec les casques difficiles | G32: 9.2 | H32: 8.9 | I32: 8.8 | J32: 8.8 | K32: 8.8 | L32: 8.9 | M32: 8.8 | N32: 7 | O32: 9.5 | P32: 8.5 | Q32: =IF(COUNT(G32:P32)=10,ROUND((G32*'Pondérations'!$B$5+H32*'Pondérations'!$B$6+I32*'Pondérations'!$B$7+J32*'Pondérations'!$B$8+K32*'Pondérations'!$B$9+L32*'Pondérations'!$B$10+M32*'Pondérations'!$B$11+N32*'Pondérations'!$B$12+O32*'Pondérations'!$B$13+P32*'Pondérations'!$B$14)/'Pondérations'!$B$16,3),"") | R32: =IF(Q32="","",1+COUNTIF($Q$7:$Q$178,">"&Q32)+COUNTIF($Q$7:Q32,Q32)-1) | V32: Élevée | W32: Headfonics import | X32: 8.3 | Y32: Award | Z32: 46209 | AA32: 1 | AB32: https://headfonics.com/?s=AFUL+ICEBORNE | AC32: Dual CS43198 dongle DAC, up to 300 mW | AD32: Ajout Headfonics | AE32: 2 | AF32: 132 | AG32: Dongle neutre, transparent et agréable, surtout convaincant par sa propreté et son espace. | AH32: Neutre/analytique mais non fatigant. | AI32: Scène au-dessus de la moyenne et bonne transparence. | AJ32: Réserve de puissance limitée avec les casques difficiles. | AK32: https://headfonics.com/aful-iceborne-review/ | AL32: 4 | AM32: Élevée — 3+ sources, domaines variés | AN32: https://www.reddit.com/r/iems/comments/1tlm1cs/the_aful_iceborne_very_nice_but_worth_the_price/ | AO32: https://note.com/oto_iro_enpi/n/ncdcf63f3cf7b | AP32: https://audio-syumi70620.hatenablog.com/entry/2026/05/09/181031 | AQ32: Objectif atteint | AR32: Communauté Reddit: 1; Review éditoriale: 3
A33: Fosi Audio | B33: MD3 | C33: Portable Amp/DAC (Headfonics) | D33: Neutre, légèrement doux dans les médiums. | E33: Microdétail, propreté/contrôle, layering | F33: Grave pas le plus ferme | G33: 9.2 | H33: 9.3 | I33: 8.5 | J33: 8.4 | K33: 8.7 | L33: 8.8 | M33: 8 | N33: 7.8 | O33: 8 | P33: 8.1 | Q33: =IF(COUNT(G33:P33)=10,ROUND((G33*'Pondérations'!$B$5+H33*'Pondérations'!$B$6+I33*'Pondérations'!$B$7+J33*'Pondérations'!$B$8+K33*'Pondérations'!$B$9+L33*'Pondérations'!$B$10+M33*'Pondérations'!$B$11+N33*'Pondérations'!$B$12+O33*'Pondérations'!$B$13+P33*'Pondérations'!$B$14)/'Pondérations'!$B$16,3),"") | R33: =IF(Q33="","",1+COUNTIF($Q$7:$Q$178,">"&Q33)+COUNTIF($Q$7:Q33,Q33)-1) | V33: Élevée | W33: Headfonics import | X33: 7.9 | Y33: Award | Z33: 46207 | AA33: 1 | AB33: https://headfonics.com/?s=Fosi+Audio+MD3 | AC33: MagSafe ES9039Q2M portable DAC/amp, 180 mW | AD33: Ajout Headfonics | AE33: 3 | AF33: 132 | AG33: Restitution neutre et transparente avec beaucoup de microdétails et un aigu aéré, sans agressivité marquée. | AH33: Neutre, légèrement doux dans les médiums. | AI33: Scène spacieuse, plutôt large que profonde, mais séparation avant/arrière satisfaisante. | AJ33: Grave pas le plus ferme; dynamique moins explosive avec des casques. | AK33: https://headfonics.com/fosi-audio-md3-review/ | AL33: 4 | AM33: Élevée — 3+ sources, domaines variés | AN33: https://www.headfonia.com/fosi-audio-md3-review/ | AO33: https://moonstarreviews.net/fosi-audio-md3-review/ | AP33: https://www.ecoustics.com/reviews/fosi-audio-md3/ | AQ33: Objectif atteint | AR33: Review éditoriale: 4
A34: iFi audio | B34: GO link 2 | C34: Portable Amp/DAC (Headfonics) | D34: Neutre à légèrement énergique | E34: Microdétail, propreté/contrôle, image 3d | F34: Peut durcir à fort volume et manque de réserve avec les casques exigeants | G34: 9.3 | H34: 9.1 | I34: 8.9 | J34: 9 | K34: 9 | L34: 9 | M34: 9 | N34: 7 | O34: 9.5 | P34: 9 | Q34: =IF(COUNT(G34:P34)=10,ROUND((G34*'Pondérations'!$B$5+H34*'Pondérations'!$B$6+I34*'Pondérations'!$B$7+J34*'Pondérations'!$B$8+K34*'Pondérations'!$B$9+L34*'Pondérations'!$B$10+M34*'Pondérations'!$B$11+N34*'Pondérations'!$B$12+O34*'Pondérations'!$B$13+P34*'Pondérations'!$B$14)/'Pondérations'!$B$16,3),"") | R34: =IF(Q34="","",1+COUNTIF($Q$7:$Q$178,">"&Q34)+COUNTIF($Q$7:Q34,Q34)-1) | V34: Élevée | W34: Headfonics import | X34: 8.1 | Y34: Award | Z34: 46197 | AA34: 1 | AB34: https://headfonics.com/?s=iFi+audio+GO+link+2 | AC34: Dual ESS dongle DAC, up to 244 mW | AD34: Ajout Headfonics | AE34: 4 | AF34: 69 | AG34: Le GO link 2 est salué pour sa clarté, sa dynamique et son grave étonnamment solide au prix demandé. Il améliore nettement une sortie téléphone/PC sans complexité. | AH34: Neutre à légèrement énergique | AI34: Bonne clarté et timing, détail supérieur aux sorties intégrées; scène propre mais pas au niveau des dongles premium. | AJ34: Peut durcir à fort volume et manque de réserve avec les casques exigeants. | AK34: https://www.techradar.com/audio/dacs/ifi-go-link-2-review | AL34: 3 | AM34: Élevée — 3+ sources, domaines variés | AN34: https://www.whathifi.com/hi-fi/dacs/ifi-go-link-2 | AO34: https://audio46.com/blogs/headphones/ifi-go-link-2-portable-dacamp-review-whats-new-in-v2 | AQ34: Objectif atteint | AR34: Review éditoriale: 3
A35: MUSE HiFi | B35: M3 Ultra | C35: Portable Amp/DAC (Headfonics) | D35: Engageant, grave épais, aigu aéré. | E35: Image 3d, profondeur, matière/timbres | F35: Peut montrer ses limites à fort volume avec des casques exigeants | G35: 9.1 | H35: 8.8 | I35: 8.9 | J35: 8.9 | K35: 8.8 | L35: 9.1 | M35: 8.9 | N35: 7.8 | O35: 8 | P35: 8.4 | Q35: =IF(COUNT(G35:P35)=10,ROUND((G35*'Pondérations'!$B$5+H35*'Pondérations'!$B$6+I35*'Pondérations'!$B$7+J35*'Pondérations'!$B$8+K35*'Pondérations'!$B$9+L35*'Pondérations'!$B$10+M35*'Pondérations'!$B$11+N35*'Pondérations'!$B$12+O35*'Pondérations'!$B$13+P35*'Pondérations'!$B$14)/'Pondérations'!$B$16,3),"") | R35: =IF(Q35="","",1+COUNTIF($Q$7:$Q$178,">"&Q35)+COUNTIF($Q$7:Q35,Q35)-1) | V35: Élevée | W35: Headfonics import | X35: 8.3 | Y35: Award | Z35: 46181 | AA35: 1 | AB35: https://headfonics.com/?s=MUSE+HiFi+M3+Ultra | AC35: ES9028Q2M + dual JAN6418 tube portable amp, 480 mW | AD35: Ajout Headfonics | AE35: 5 | AF35: 109 | AG35: Son très transparent et spectaculaire, avec grave ample et aigu étendu; l’effet de scène est un vrai point fort. | AH35: Engageant, grave épais, aigu aéré. | AI35: Très grande scène, décrite comme holographique. | AJ35: Peut montrer ses limites à fort volume avec des casques exigeants. | AK35: https://headfonics.com/muse-hifi-m3-ultra-review/ | AL35: 4 | AM35: Élevée — 3+ sources, domaines variés | AN35: https://www.ecoustics.com/reviews/muse-hifi-m3-ultra/ | AO35: https://primeaudio.org/muse-hifi-m3-ultra-review/ | AP35: https://nextrift.com/202643639/ | AQ35: Objectif atteint | AR35: Review éditoriale: 4
A36: xDuoo | B36: Link3 | C36: Portable Amp/DAC (Headfonics) | D36: Légèrement chaleureux/analogique. | E36: Matière/timbres, profondeur, image 3d | F36: Format assez gros et chauffe sensiblement | G36: 9 | H36: 8.9 | I36: 8.9 | J36: 8.8 | K36: 8.9 | L36: 9.3 | M36: 9 | N36: 9 | O36: 7 | P36: 8.5 | Q36: =IF(COUNT(G36:P36)=10,ROUND((G36*'Pondérations'!$B$5+H36*'Pondérations'!$B$6+I36*'Pondérations'!$B$7+J36*'Pondérations'!$B$8+K36*'Pondérations'!$B$9+L36*'Pondérations'!$B$10+M36*'Pondérations'!$B$11+N36*'Pondérations'!$B$12+O36*'Pondérations'!$B$13+P36*'Pondérations'!$B$14)/'Pondérations'!$B$16,3),"") | R36: =IF(Q36="","",1+COUNTIF($Q$7:$Q$178,">"&Q36)+COUNTIF($Q$7:Q36,Q36)-1) | V36: Élevée | W36: Headfonics import | X36: 8.6 | Y36: Award | Z36: 46178 | AA36: 1 | AB36: https://headfonics.com/?s=xDuoo+Link3 | AC36: Dongle DAC with microSD slot | AD36: Ajout Headfonics | AE36: 6 | AF36: 239 | AG36: Présentation dynamique et propre, avec un côté analogique et musical plutôt qu’analytique. | AH36: Légèrement chaleureux/analogique. | AI36: Scène au-dessus de la moyenne, bonne dynamique et grave solide. | AJ36: Format assez gros et chauffe sensiblement. | AK36: https://headfonics.com/xduoo-link3-review/ | AL36: 4 | AM36: Élevée — 3+ sources, domaines variés | AN36: https://primeaudio.org/xduoo-link3-review/ | AO36: https://moonstarreviews.net/xduoo-link3-review/ | AP36: https://www.hifidaydreaming.com/post/portable-class-a-amp-dac-with-unique-twist-xduoo-link-3-review | AQ36: Objectif atteint | AR36: Review éditoriale: 4
A37: xDuoo | B37: XP-2 Bal | C37: Portable Amp/DAC (Headfonics) | D37: Neutre, analytique mais pas clinique. | E37: Microdétail, layering, propreté/contrôle | F37: Recharge lente | G37: 9.3 | H37: 9.2 | I37: 9 | J37: 8.9 | K37: 9.1 | L37: 8.7 | M37: 9.1 | N37: 8.7 | O37: 8 | P37: 8.8 | Q37: =IF(COUNT(G37:P37)=10,ROUND((G37*'Pondérations'!$B$5+H37*'Pondérations'!$B$6+I37*'Pondérations'!$B$7+J37*'Pondérations'!$B$8+K37*'Pondérations'!$B$9+L37*'Pondérations'!$B$10+M37*'Pondérations'!$B$11+N37*'Pondérations'!$B$12+O37*'Pondérations'!$B$13+P37*'Pondérations'!$B$14)/'Pondérations'!$B$16,3),"") | R37: =IF(Q37="","",1+COUNTIF($Q$7:$Q$178,">"&Q37)+COUNTIF($Q$7:Q37,Q37)-1) | V37: Élevée | W37: Headfonics import | X37: 8.4 | Y37: Award | Z37: 46157 | AA37: 1 | AB37: https://headfonics.com/?s=xDuoo+XP-2+Bal | AC37: Portable DAC/amp, balanced 320 mW, Bluetooth | AD37: Ajout Headfonics | AE37: 7 | AF37: 149 | AG37: Portable très détaillé et transparent, techniquement solide sans devenir froid. | AH37: Neutre, analytique mais pas clinique. | AI37: Bonne scène, grave tendu et lecture précise. | AJ37: Recharge lente; moins orienté couleur/matière. | AK37: https://headfonics.com/xduoo-xp-2-bal-review/ | AL37: 4 | AM37: Élevée — 3+ sources, domaines variés | AN37: https://www.youtube.com/watch?v=V-sVneIc1DQ | AO37: https://www.head-fi.org/threads/xduoo-xp-2-bal-balanced-bluetooth-dac-amp-now-on-apos-audio.966945/ | AP37: https://www.reddit.com/r/iems/comments/1gj8g45 | AQ37: Objectif atteint | AR37: Communauté Reddit: 1; Head-Fi forum: 1; Review éditoriale: 1; Vidéo review: 1
A38: iBasso | B38: PB6 MACAW | C38: Portable Amp/DAC (Headfonics) | D38: Tube doux, ample et riche. | E38: Matière/timbres, puissance, profondeur | F38: Encombrant | G38: 9 | H38: 8.7 | I38: 9 | J38: 8.9 | K38: 8.9 | L38: 9.5 | M38: 8.9 | N38: 9.3 | O38: 6.5 | P38: 8.5 | Q38: =IF(COUNT(G38:P38)=10,ROUND((G38*'Pondérations'!$B$5+H38*'Pondérations'!$B$6+I38*'Pondérations'!$B$7+J38*'Pondérations'!$B$8+K38*'Pondérations'!$B$9+L38*'Pondérations'!$B$10+M38*'Pondérations'!$B$11+N38*'Pondérations'!$B$12+O38*'Pondérations'!$B$13+P38*'Pondérations'!$B$14)/'Pondérations'!$B$16,3),"") | R38: =IF(Q38="","",1+COUNTIF($Q$7:$Q$178,">"&Q38)+COUNTIF($Q$7:Q38,Q38)-1) | V38: Élevée | W38: Headfonics import | X38: 9 | Y38: Award | Z38: 46081 | AA38: 1 | AB38: https://headfonics.com/?s=iBasso+PB6+MACAW | AC38: Quad JAN6418 tube portable headphone amplifier, up to 2.3 W | AD38: Ajout Headfonics | AE38: 9 | AF38: 438 | AG38: Ampli tube portable très puissant, fluide et expansif, tout en gardant un fond noir remarquable. | AH38: Tube doux, ample et riche. | AI38: Scène expansive et bon contrôle même avec des IEM sensibles. | AJ38: Encombrant; microphonie/tubes et protection physique à surveiller. | AK38: https://headfonics.com/ibasso-pb6-macaw-review/ | AL38: 4 | AM38: Élevée — 3+ sources, domaines variés | AN38: https://www.audiophile-heaven.com/2026/04/ibasso-pb6-macaw-tube-amplifier-review-portable-glow-of-magic-power.html | AO38: https://bloomaudio.com/blogs/articles/macaw-some-ibasso-pb6-macaw-review | AP38: https://www.open-end-music.com/forum/audiophile-kopfh%C3%B6rer/kh-kopfh%C3%B6rer-testberichte-rezensionen/768928-test-ibasso-pb6 | AQ38: Objectif atteint | AR38: Review éditoriale: 4
A39: HiBy | B39: W4 | C39: Portable Amp/DAC (Headfonics) | D39: Neutre avec légère euphonie et aigu aéré. | E39: Dynamique, layering, propreté/contrôle | F39: Commande de volume jugée particulière | G39: 9.1 | H39: 8.2 | I39: 8.8 | J39: 8.6 | K39: 8.9 | L39: 8.4 | M39: 8.4 | N39: 9.1 | O39: 8 | P39: 8.3 | Q39: =IF(COUNT(G39:P39)=10,ROUND((G39*'Pondérations'!$B$5+H39*'Pondérations'!$B$6+I39*'Pondérations'!$B$7+J39*'Pondérations'!$B$8+K39*'Pondérations'!$B$9+L39*'Pondérations'!$B$10+M39*'Pondérations'!$B$11+N39*'Pondérations'!$B$12+O39*'Pondérations'!$B$13+P39*'Pondérations'!$B$14)/'Pondérations'!$B$16,3),"") | R39: =IF(Q39="","",1+COUNTIF($Q$7:$Q$178,">"&Q39)+COUNTIF($Q$7:Q39,Q39)-1) | V39: Élevée | W39: Headfonics import | X39: 8.3 | Y39: Award | Z39: 46066 | AA39: 1 | AB39: https://headfonics.com/?s=HiBy+W4 | AC39: Bluetooth 5.4 dual-DAC portable amp, up to 475 mW | AD39: Ajout Headfonics | AE39: 10 | AF39: 87 | AG39: Bluetooth DAC agréable et euphonic, davantage musical que technique. | AH39: Neutre avec légère euphonie et aigu aéré. | AI39: Scène spacieuse mais résolution moins analytique. | AJ39: Commande de volume jugée particulière. | AK39: https://headfonics.com/hiby-w4-review/ | AL39: 4 | AM39: Élevée — 3+ sources, domaines variés | AN39: https://www.headfonia.com/hiby-w4-review/ | AO39: https://www.audiophile-heaven.com/2026/06/hiby-w4-portable-hifi-bluetooth-headphone-amplifier-review-dual-core-dual-mode-uncharge-dac.html | AP39: https://mobileaudiophile.com/wireless/hiby-w4-review/ | AQ39: Objectif atteint | AR39: Review éditoriale: 4
A40: Questyle | B40: SIGMA Pro | C40: Portable Amp/DAC (Headfonics) | D40: Neutre/analytique. | E40: Propreté/contrôle, puissance, dynamique | F40: Peu d’options de réglage | G40: 9.6 | H40: 9 | I40: 8.4 | J40: 8.3 | K40: 8.9 | L40: 8.5 | M40: 9.1 | N40: 9.4 | O40: 8 | P40: 8 | Q40: =IF(COUNT(G40:P40)=10,ROUND((G40*'Pondérations'!$B$5+H40*'Pondérations'!$B$6+I40*'Pondérations'!$B$7+J40*'Pondérations'!$B$8+K40*'Pondérations'!$B$9+L40*'Pondérations'!$B$10+M40*'Pondérations'!$B$11+N40*'Pondérations'!$B$12+O40*'Pondérations'!$B$13+P40*'Pondérations'!$B$14)/'Pondérations'!$B$16,3),"") | R40: =IF(Q40="","",1+COUNTIF($Q$7:$Q$178,">"&Q40)+COUNTIF($Q$7:Q40,Q40)-1) | V40: Élevée | W40: Headfonics import | X40: 8.6 | Y40: Award | Z40: 46053 | AA40: 1 | AB40: https://headfonics.com/?s=Questyle+SIGMA+Pro | AC40: Bluetooth-capable Current Mode portable DAC/amp | AD40: Ajout Headfonics | AE40: 11 | AF40: 790 | AG40: Portable résolument studio : très propre, équilibré et détaillé, visant la fidélité plutôt que la coloration. | AH40: Neutre/analytique. | AI40: Bonne précision et lisibilité des plans. | AJ40: Peu d’options de réglage; construction vitrée fragile. | AK40: https://headfonics.com/questyle-sigma-pro-review/ | AL40: 4 | AM40: Élevée — 3+ sources, domaines variés | AN40: https://kropka.audio/test/wzmacniacze/questyle-sigma-pro-recenzja/ | AO40: https://www.dtmstation.com/archives/75475.html | AP40: https://www.fujiya-avic.co.jp/blog/detail/996 | AQ40: Objectif atteint | AR40: Review éditoriale: 4
...

Sheet Technique & sources
A1: Colonnes D à K : vérification unitaire sur sources primaires, 2026-08-10. Une cellule remplie = valeur attestée par une source ouverte et citée (voir feuille « Sources technique »). Une cellule VIDE = non vérifiable avec certitude, ce n’est pas un « non ». Les remplissages automatiques antérieurs de F-K ont été effacés.
A2: Données techniques, prix indicatifs et sources
A3: Un repère de prix par produit. Les prix déjà consolidés sont conservés; les compléments utilisent un prix européen direct quand disponible, sinon un MSRP/prix de lancement converti en euros au taux ECB du 29/07/2026. Source et devise d’origine : commentaire de la cellule prix.
